Workbook

Sheet Summary
A1: Signals System — Backtest Results
A2: Top 100 US stocks by liquidity · 10-year daily history · long-only · scoring engine v1 (untuned)
A4: Test parameters
A5: Universe | B5: Top 100 S&P 500 by dollar volume
A6: History | B6: ~10 years daily (Yahoo, split/div-adjusted)
A7: Direction | B7: Long only
A8: Costs | B8: 15 bps/side (10 fee + 5 slippage)
A9: Risk exits | B9: 10% stop-loss · 60-bar max hold
A10: Entry / exit threshold | B10: 6.0 / 5.0 (untuned defaults)
A12: Pooled-trade results (every trade across all symbols)
A13: Total trades | B13: 3770 | C13: Source: backtest engine
A14: Win rate | B14: 0.45119363 | C14: Source: backtest engine
A15: Profit factor | B15: 1.7797111 | C15: Source: backtest engine
A16: Expectancy / trade | B16: 0.027099596 | C16: Source: backtest engine
A17: Average win | B17: 0.13709311 | C17: Source: backtest engine
A18: Average loss | B18: -0.063330066 | C18: Source: backtest engine
A20: Per-symbol results (live formulas from 'Per Symbol' sheet)
A21: Symbols tested | B21: =COUNTA('Per Symbol'!A2:A101) -> 100
A22: % symbols profitable | B22: =COUNTIF('Per Symbol'!D2:D101,">0")/COUNTA('Per Symbol'!A2:A101) -> 0.84
A23: % symbols beat buy&hold | B23: =COUNTIF('Per Symbol'!G2:G101,TRUE())/COUNTA('Per Symbol'!A2:A101) -> 0.06
A24: Median symbol return | B24: =MEDIAN('Per Symbol'!D2:D101) -> 0.59862918
A25: Average symbol return | B25: =AVERAGE('Per Symbol'!D2:D101) -> 1.6838647
A26: Average buy & hold | B26: =AVERAGE('Per Symbol'!F2:F101) -> 12.398382
A27: Average max drawdown | B27: =AVERAGE('Per Symbol'!E2:E101) -> -0.39116716
A30: How to read this
A31: Win rate ~45% but profit factor 1.78 and positive expectancy: the edge comes from
A32: asymmetry — average winner (+13.7%) is ~2x the average loser (-6.3%).
A33: Only ~6% of names beat buy & hold: these mega-caps were in strong 10-year uptrends,
A34: so a long-only system sitting in cash part of the time lags a melt-up. The strategy's
A35: value is selectivity and smaller drawdowns, not out-returning a raging bull.
A36: CAVEATS: backtested (not forward-tested); survivorship bias (today's top-100 are winners);
A37: weights are untuned defaults; single long-only sizing, no portfolio capital constraint.
A38: Not financial advice.

Sheet Per Symbol
A1: Symbol | B1: Trades | C1: Win rate | D1: Total return | E1: Max drawdown | F1: Buy & hold | G1: Beat B&H?
A2: TSLA | B2: 29 | C2: 0.62068966 | D2: 19.959177 | E2: -0.23349739 | F2: 29.587321 | G2: =FALSE() -> FALSE
A3: DELL | B3: 35 | C3: 0.62857143 | D3: 17.277487 | E3: -0.38465001 | F3: 36.293283 | G3: =FALSE() -> FALSE
A4: APP | B4: 18 | C4: 0.38888889 | D4: 12.79726 | E4: -0.27691937 | F4: 6.2041413 | G4: =TRUE() -> TRUE
A5: AMD | B5: 40 | C5: 0.45 | D5: 10.152145 | E5: -0.31172685 | F5: 102.14203 | G5: =FALSE() -> FALSE
A6: VRT | B6: 25 | C6: 0.6 | D6: 7.9459687 | E6: -0.33014538 | F6: 32.515641 | G6: =FALSE() -> FALSE
A7: NVDA | B7: 38 | C7: 0.47368421 | D7: 7.0509726 | E7: -0.36555779 | F7: 176.23835 | G7: =FALSE() -> FALSE
A8: FTNT | B8: 39 | C8: 0.46153846 | D8: 6.093808 | E8: -0.44503548 | F8: 20.085373 | G8: =FALSE() -> FALSE
A9: CRWD | B9: 19 | C9: 0.63157895 | D9: 4.8307807 | E9: -0.30898362 | F9: 10.807931 | G9: =FALSE() -> FALSE
A10: SNDK | B10: 5 | C10: 0.6 | D10: 4.233448 | E10: -0.078873658 | F10: 59.6875 | G10: =FALSE() -> FALSE
A11: PLTR | B11: 21 | C11: 0.47619048 | D11: 4.2134746 | E11: -0.37977723 | F11: 12.523158 | G11: =FALSE() -> FALSE
A12: MS | B12: 41 | C12: 0.53658537 | D12: 3.8920486 | E12: -0.31311166 | F12: 9.8495779 | G12: =FALSE() -> FALSE
A13: NFLX | B13: 37 | C13: 0.48648649 | D13: 3.8564582 | E13: -0.23015759 | F13: 7.4420679 | G13: =FALSE() -> FALSE
A14: LLY | B14: 38 | C14: 0.5 | D14: 3.7912205 | E14: -0.34941887 | F14: 16.460504 | G14: =FALSE() -> FALSE
A15: LRCX | B15: 35 | C15: 0.6 | D15: 3.5564259 | E15: -0.38457152 | F15: 50.096553 | G15: =FALSE() -> FALSE
A16: AAPL | B16: 35 | C16: 0.62857143 | D16: 3.4834005 | E16: -0.35109268 | F16: 12.621993 | G16: =FALSE() -> FALSE
... A35: GS | B35: 39 | C35: 0.46153846 | D35: 1.0979576 | E35: -0.3045609 | F35: 7.8246788 | G35: =FALSE() -> FALSE
A36: BA | B36: 34 | C36: 0.47058824 | D36: 1.0746023 | E36: -0.50527749 | F36: 0.82757407 | G36: =TRUE() -> TRUE
A37: MU | B37: 44 | C37: 0.47727273 | D37: 1.0304656 | E37: -0.71333777 | F37: 81.75616 | G37: =FALSE() -> FALSE
A38: C | B38: 37 | C38: 0.48648649 | D38: 0.99518924 | E38: -0.44520361 | F38: 3.3406287 | G38: =FALSE() -> FALSE
A39: GE | B39: 40 | C39: 0.45 | D39: 0.96698955 | E39: -0.52464186 | F39: 1.6698251 | G39: =FALSE() -> FALSE
A40: CHTR | B40: 31 | C40: 0.5483871 | D40: 0.92324651 | E40: -0.2550082 | F40: -0.43865342 | G40: =TRUE() -> TRUE
A41: META | B41: 36 | C41: 0.47222222 | D41: 0.89375201 | E41: -0.35530424 | F41: 4.0598608 | G41: =FALSE() -> FALSE
A42: XOM | B42: 38 | C42: 0.44736842 | D42: 0.86342618 | E42: -0.17992585 | F42: 1.3170592 | G42: =FALSE() -> FALSE
A43: WMT | B43: 45 | C43: 0.53333333 | D43: 0.86203849 | E43: -0.2365133 | F43: 4.7876119 | G43: =FALSE() -> FALSE
A44: COHR | B44: 38 | C44: 0.44736842 | D44: 0.86143238 | E44: -0.77141369 | F44: 18.675254 | G44: =FALSE() -> FALSE
A45: HOOD | B45: 21 | C45: 0.33333333 | D45: 0.83347794 | E45: -0.61460718 | F45: 2.1059736 | G45: =FALSE() -> FALSE
A46: COP | B46: 36 | C46: 0.36111111 | D46: 0.79861714 | E46: -0.35010126 | F46: 2.21453 | G46: =FALSE() -> FALSE
A47: ORCL | B47: 41 | C47: 0.46341463 | D47: 0.78886231 | E47: -0.26876566 | F47: 4.241414 | G47: =FALSE() -> FALSE
A48: GOOGL | B48: 38 | C48: 0.57894737 | D48: 0.78153088 | E48: -0.27719196 | F48: 9.3877192 | G48: =FALSE() -> FALSE
A49: SCHW | B49: 38 | C49: 0.44736842 | D49: 0.73016385 | E49: -0.5252491 | F49: 2.5086432 | G49: =FALSE() -> FALSE
A50: HD | B50: 37 | C50: 0.54054054 | D50: 0.64196792 | E50: -0.17996036 | F50: 2.3179357 | G50: =FALSE() -> FALSE
A51: HPE | B51: 35 | C51: 0.45714286 | D51: 0.60035829 | E51: -0.49738448 | F51: 4.4858459 | G51: =FALSE() -> FALSE
A52: ON | B52: 38 | C52: 0.34210526 | D52: 0.59690008 | E52: -0.64823264 | F52: 11.322189 | G52: =FALSE() -> FALSE
... A71: SMCI | B71: 34 | C71: 0.47058824 | D71: 0.2402967 | E71: -0.71970349 | F71: 10.436031 | G71: =FALSE() -> FALSE
A72: PFE | B72: 33 | C72: 0.42424242 | D72: 0.22200848 | E72: -0.28906886 | F72: 0.19906287 | G72: =TRUE() -> TRUE
A73: JNJ | B73: 44 | C73: 0.40909091 | D73: 0.21060267 | E73: -0.31966526 | F73: 1.558146 | G73: =FALSE() -> FALSE
A74: MA | B74: 41 | C74: 0.43902439 | D74: 0.1995179 | E74: -0.35166843 | F74: 4.430147 | G74: =FALSE() -> FALSE
A75: SATS | B75: 38 | C75: 0.26315789 | D75: 0.18997049 | E75: -0.77090133 | F75: 2.3771815 | G75: =FALSE() -> FALSE
A76: NOW | B76: 44 | C76: 0.38636364 | D76: 0.17366197 | E76: -0.63144732 | F76: 5.32083 | G76: =FALSE() -> FALSE
...
